Traceback (most recent call last):
  File "C:\Users\pmarshal\Anaconda3\lib\site-packages\jupyter_cache\executors\utils.py", line 58, in single_nb_execution
    executenb(
  File "C:\Users\pmarshal\Anaconda3\lib\site-packages\nbclient\client.py", line 1305, in execute
    return NotebookClient(nb=nb, resources=resources, km=km, **kwargs).execute()
  File "C:\Users\pmarshal\Anaconda3\lib\site-packages\jupyter_core\utils\__init__.py", line 165, in wrapped
    return loop.run_until_complete(inner)
  File "C:\Users\pmarshal\Anaconda3\lib\asyncio\base_events.py", line 647, in run_until_complete
    return future.result()
  File "C:\Users\pmarshal\Anaconda3\lib\site-packages\nbclient\client.py", line 705, in async_execute
    await self.async_execute_cell(
  File "C:\Users\pmarshal\Anaconda3\lib\site-packages\nbclient\client.py", line 1058, in async_execute_cell
    await self._check_raise_for_error(cell, cell_index, exec_reply)
  File "C:\Users\pmarshal\Anaconda3\lib\site-packages\nbclient\client.py", line 914, in _check_raise_for_error
    raise CellExecutionError.from_cell_and_msg(cell, exec_reply_content)
nbclient.exceptions.CellExecutionError: An error occurred while executing the following cell:
------------------
just_2024 = danger_filter.loc[(danger_filter['year']==2024)]
rating_counts_df = just_2024['rating'].value_counts()
#rating_counts_df = pd.DataFrame({'Rating': rating_counts.index, 'Count': rating_counts.values})
# Define a custom order for the ratings
custom_order = ['Very Low', 'Low', 'Moderate', 'High', 'Extreme']

# Apply the custom order and sort the DataFrame
rating_counts_df['Rating'] = pd.Categorical(rating_counts_df['rating'], categories=custom_order, ordered=True)
rating_counts_df = rating_counts_df.sort_values('Rating')

# Define the mapping of 'Rating' to numerical values
rating_mapping = {'Very Low': 1, 'Low': 2, 'Moderate': 3, 'High': 4, 'Extreme': 5}

# Add the 'danger' column based on the mapping
rating_counts_df['danger'] = rating_counts_df['Rating'].map(rating_mapping)
rating_counts_df
------------------


[1;31m---------------------------------------------------------------------------[0m
[1;31mKeyError[0m                                  Traceback (most recent call last)
File [1;32m~\Anaconda3\lib\site-packages\pandas\core\indexes\base.py:3802[0m, in [0;36mIndex.get_loc[1;34m(self, key, method, tolerance)[0m
[0;32m   3801[0m [38;5;28;01mtry[39;00m:
[1;32m-> 3802[0m     [38;5;28;01mreturn[39;00m [38;5;28;43mself[39;49m[38;5;241;43m.[39;49m[43m_engine[49m[38;5;241;43m.[39;49m[43mget_loc[49m[43m([49m[43mcasted_key[49m[43m)[49m
[0;32m   3803[0m [38;5;28;01mexcept[39;00m [38;5;167;01mKeyError[39;00m [38;5;28;01mas[39;00m err:

File [1;32m~\Anaconda3\lib\site-packages\pandas\_libs\index.pyx:138[0m, in [0;36mpandas._libs.index.IndexEngine.get_loc[1;34m()[0m

File [1;32m~\Anaconda3\lib\site-packages\pandas\_libs\index.pyx:165[0m, in [0;36mpandas._libs.index.IndexEngine.get_loc[1;34m()[0m

File [1;32mpandas\_libs\hashtable_class_helper.pxi:5745[0m, in [0;36mpandas._libs.hashtable.PyObjectHashTable.get_item[1;34m()[0m

File [1;32mpandas\_libs\hashtable_class_helper.pxi:5753[0m, in [0;36mpandas._libs.hashtable.PyObjectHashTable.get_item[1;34m()[0m

[1;31mKeyError[0m: 'rating'

The above exception was the direct cause of the following exception:

[1;31mKeyError[0m                                  Traceback (most recent call last)
Cell [1;32mIn[19], line 8[0m
[0;32m      5[0m custom_order [38;5;241m=[39m [[38;5;124m'[39m[38;5;124mVery Low[39m[38;5;124m'[39m, [38;5;124m'[39m[38;5;124mLow[39m[38;5;124m'[39m, [38;5;124m'[39m[38;5;124mModerate[39m[38;5;124m'[39m, [38;5;124m'[39m[38;5;124mHigh[39m[38;5;124m'[39m, [38;5;124m'[39m[38;5;124mExtreme[39m[38;5;124m'[39m]
[0;32m      7[0m [38;5;66;03m# Apply the custom order and sort the DataFrame[39;00m
[1;32m----> 8[0m rating_counts_df[[38;5;124m'[39m[38;5;124mRating[39m[38;5;124m'[39m] [38;5;241m=[39m pd[38;5;241m.[39mCategorical([43mrating_counts_df[49m[43m[[49m[38;5;124;43m'[39;49m[38;5;124;43mrating[39;49m[38;5;124;43m'[39;49m[43m][49m, categories[38;5;241m=[39mcustom_order, ordered[38;5;241m=[39m[38;5;28;01mTrue[39;00m)
[0;32m      9[0m rating_counts_df [38;5;241m=[39m rating_counts_df[38;5;241m.[39msort_values([38;5;124m'[39m[38;5;124mRating[39m[38;5;124m'[39m)
[0;32m     11[0m [38;5;66;03m# Define the mapping of 'Rating' to numerical values[39;00m

File [1;32m~\Anaconda3\lib\site-packages\pandas\core\series.py:981[0m, in [0;36mSeries.__getitem__[1;34m(self, key)[0m
[0;32m    978[0m     [38;5;28;01mreturn[39;00m [38;5;28mself[39m[38;5;241m.[39m_values[key]
[0;32m    980[0m [38;5;28;01melif[39;00m key_is_scalar:
[1;32m--> 981[0m     [38;5;28;01mreturn[39;00m [38;5;28;43mself[39;49m[38;5;241;43m.[39;49m[43m_get_value[49m[43m([49m[43mkey[49m[43m)[49m
[0;32m    983[0m [38;5;28;01mif[39;00m is_hashable(key):
[0;32m    984[0m     [38;5;66;03m# Otherwise index.get_value will raise InvalidIndexError[39;00m
[0;32m    985[0m     [38;5;28;01mtry[39;00m:
[0;32m    986[0m         [38;5;66;03m# For labels that don't resolve as scalars like tuples and frozensets[39;00m

File [1;32m~\Anaconda3\lib\site-packages\pandas\core\series.py:1089[0m, in [0;36mSeries._get_value[1;34m(self, label, takeable)[0m
[0;32m   1086[0m     [38;5;28;01mreturn[39;00m [38;5;28mself[39m[38;5;241m.[39m_values[label]
[0;32m   1088[0m [38;5;66;03m# Similar to Index.get_value, but we do not fall back to positional[39;00m
[1;32m-> 1089[0m loc [38;5;241m=[39m [38;5;28;43mself[39;49m[38;5;241;43m.[39;49m[43mindex[49m[38;5;241;43m.[39;49m[43mget_loc[49m[43m([49m[43mlabel[49m[43m)[49m
[0;32m   1090[0m [38;5;28;01mreturn[39;00m [38;5;28mself[39m[38;5;241m.[39mindex[38;5;241m.[39m_get_values_for_loc([38;5;28mself[39m, loc, label)

File [1;32m~\Anaconda3\lib\site-packages\pandas\core\indexes\base.py:3804[0m, in [0;36mIndex.get_loc[1;34m(self, key, method, tolerance)[0m
[0;32m   3802[0m     [38;5;28;01mreturn[39;00m [38;5;28mself[39m[38;5;241m.[39m_engine[38;5;241m.[39mget_loc(casted_key)
[0;32m   3803[0m [38;5;28;01mexcept[39;00m [38;5;167;01mKeyError[39;00m [38;5;28;01mas[39;00m err:
[1;32m-> 3804[0m     [38;5;28;01mraise[39;00m [38;5;167;01mKeyError[39;00m(key) [38;5;28;01mfrom[39;00m [38;5;21;01merr[39;00m
[0;32m   3805[0m [38;5;28;01mexcept[39;00m [38;5;167;01mTypeError[39;00m:
[0;32m   3806[0m     [38;5;66;03m# If we have a listlike key, _check_indexing_error will raise[39;00m
[0;32m   3807[0m     [38;5;66;03m#  InvalidIndexError. Otherwise we fall through and re-raise[39;00m
[0;32m   3808[0m     [38;5;66;03m#  the TypeError.[39;00m
[0;32m   3809[0m     [38;5;28mself[39m[38;5;241m.[39m_check_indexing_error(key)

[1;31mKeyError[0m: 'rating'

